<!-- MIT Mini Cheetah XML 
    Source: https://github.com/deepmind/mujoco/issues/112
-->
<mujoco model="mini_cheetah">

    <compiler angle="radian" meshdir="../meshes/" />
    <size njmax="500" nconmax="100" />
    <option gravity='0 0 -9.806' iterations='50' solver='Newton' timestep='0.001'/>s

    <default>
        <geom contype="1" conaffinity="1" friction="0.8 0.8 0.3" rgba="0.5 0.6 0.7 1" margin="0.001" group="0"/>

        <light castshadow="false" diffuse="1 1 1"/>
        <motor ctrlrange="-33.5 33.5" ctrllimited="true"/>
        <camera fovy="60"/>
        <joint damping="0.01" armature="0.01"/>

    </default>

    <asset>
        <mesh name="mini_body" file="mini_body.stl" />
        <mesh name="mini_abad" file="mini_abad.stl" />
        <mesh name="mini_upper_link" file="mini_upper_link.stl" />
        <mesh name="mini_lower_link" file="mini_lower_link.stl" />
    </asset>

    <asset>
        <texture type="skybox" builtin="gradient" rgb1="0.3 0.5 0.7" rgb2="0 0 0" width="512" height="512"/>
        <texture name="plane" type="2d" builtin="flat" rgb1=".2 .3 .4" rgb2=".1 0.15 0.2" width="512" height="512" mark="cross" markrgb="0 0 0"/>
        <material name="plane" reflectance="0.0" texture="plane" texrepeat="3 3" texuniform="true"/>
    </asset>

    <visual>
        <rgba com="0.502 1.0 0 0.5" contactforce="0.98 0.4 0.4 0.7" contactpoint="1.0 1.0 0.6 0.4"/>
        <scale com="0.2" forcewidth="0.035" contactwidth="0.10" contactheight="0.04"/>
        <!-- <map force="0.1" zfar="30"/>
        <rgba haze="0.15 0.25 0.35 1"/>
        <quality shadowsize="2048"/>
        <global offwidth="800" offheight="800"/> -->
    </visual>

    <worldbody>
        <light directional="true" diffuse=".8 .8 .8" pos="0 0 10" dir="0 0 -10"/>
        <camera name="track" mode="trackcom" pos="0 -1.3 1.6" xyaxes="1 0 0 0 0.707 0.707"/>
        <geom name='floor' type='plane' conaffinity='1' condim='3' contype='1' rgba="0.5 0.9 0.9 0.1" material='plane' pos='0 0 0' size='0 0 1'/>

        <body name="body" pos="0 0 0.5">
            <inertial pos="0 0 0" quat="0 0.707107 0 0.707107" mass="3.3" diaginertia="0.042673 0.036203 0.011253" />
            <joint name="floating_base" type="free" />
            <geom type="mesh" contype="0" conaffinity="0" group="1" mesh="mini_body" />
            <geom type="mesh" mesh="mini_body" />
            <!-- <geom size="0.0005 0.0005 0.0005" type="box" contype="0" conaffinity="0" group="1" rgba="0.8 0 0 0" />
            <geom size="0.0005 0.0005 0.0005" type="box" rgba="0.8 0 0 0" /> -->
            <site name="imu" pos="0 0 0"/>

            <body name="abduct_fr" pos="0.19 -0.049 0">
                <inertial pos="0 0.036 0" quat="0.564242 0.568689 0.421431 0.424993" mass="0.54" diaginertia="0.000577158 0.000443992 0.00036385" />
                <joint name="torso_to_abduct_fr_j" pos="0 0 0" axis="1 0 0" />
                <geom pos="-0.055 0 0" quat="2.31078e-07 0.707105 0.707108 2.31079e-07" type="mesh" contype="0" conaffinity="0" group="1" mesh="mini_abad" />
                <geom pos="-0.055 0 0" quat="2.31078e-07 0.707105 0.707108 2.31079e-07" type="mesh" mesh="mini_abad" />
                <body name="thigh_fr" pos="0 -0.062 0">
                    <inertial pos="0 0.016 -0.02" quat="0.899267 -0.00195739 -0.00366412 0.437381" mass="0.634" diaginertia="0.001498 0.001498 0.001498" />
                    <joint name="abduct_fr_to_thigh_fr_j" pos="0 0 0" axis="0 -1 0" />
                    <geom quat="0.707105 0 -0.707108 0" type="mesh" contype="0" conaffinity="0" group="1" mesh="mini_upper_link" />
                    <geom quat="0.707105 0 -0.707108 0" type="mesh" mesh="mini_upper_link" />
                    <body name="shank_fr" pos="0 0 -0.209">
                        <inertial pos="0 0 -0.188673" quat="0.707107 0 0 0.707107" mass="0.214" diaginertia="0.000310727 0.000307727 3.1e-05" />
                        <joint name="thigh_fr_to_knee_fr_j" pos="0 0 0" axis="0 -1 0" />
                        <geom quat="3.26795e-07 0 1 0" type="mesh" contype="0" conaffinity="0" group="1" mesh="mini_lower_link" />
                        <geom quat="3.26795e-07 0 1 0" type="mesh" mesh="mini_lower_link" />
                        <geom size="0.015" pos="0 0 -0.18" contype="0" conaffinity="0" group="1" />
                        <geom size="0.015" pos="0 0 -0.18" />
                    </body>
                </body>
            </body>
            <body name="abduct_fl" pos="0.19 0.049 0">
                <inertial pos="0 0.036 0" quat="0.564242 0.568689 0.421431 0.424993" mass="0.54" diaginertia="0.000577158 0.000443992 0.00036385" />
                <joint name="torso_to_abduct_fl_j" pos="0 0 0" axis="1 0 0" />
                <geom pos="-0.055 0 0" quat="0.707105 0 0 -0.707108" type="mesh" contype="0" conaffinity="0" group="1" mesh="mini_abad" />
                <geom pos="-0.055 0 0" quat="0.707105 0 0 -0.707108" type="mesh" mesh="mini_abad" />
                <body name="thigh_fl" pos="0 0.062 0">
                    <inertial pos="0 0.016 -0.02" quat="0.899267 -0.00195739 -0.00366412 0.437381" mass="0.634" diaginertia="0.001498 0.001498 0.001498" />
                    <joint name="abduct_fl_to_thigh_fl_j" pos="0 0 0" axis="0 -1 0" />
                    <geom quat="0.707105 0 -0.707108 0" type="mesh" contype="0" conaffinity="0" group="1" mesh="mini_upper_link" />
                    <geom quat="0.707105 0 -0.707108 0" type="mesh" mesh="mini_upper_link" />
                    <body name="shank_fl" pos="0 0 -0.209">
                        <inertial pos="0 0 -0.188673" quat="0.707107 0 0 0.707107" mass="0.214" diaginertia="0.000310727 0.000307727 3.1e-05" />
                        <joint name="thigh_fl_to_knee_fl_j" pos="0 0 0" axis="0 -1 0" />
                        <geom quat="3.26795e-07 0 1 0" type="mesh" contype="0" conaffinity="0" group="1" mesh="mini_lower_link" />
                        <geom quat="3.26795e-07 0 1 0" type="mesh" mesh="mini_lower_link" />
                        <geom size="0.015" pos="0 0 -0.18" contype="0" conaffinity="0" group="1" />
                        <geom size="0.015" pos="0 0 -0.18" />
                    </body>
                </body>
            </body>
            <body name="abduct_hr" pos="-0.19 -0.049 0">
                <inertial pos="0 0.036 0" quat="0.564242 0.568689 0.421431 0.424993" mass="0.54" diaginertia="0.000577158 0.000443992 0.00036385" />
                <joint name="torso_to_abduct_hr_j" pos="0 0 0" axis="1 0 0" />
                <geom pos="0.055 0 0" quat="0.707105 0 0 0.707108" type="mesh" contype="0" conaffinity="0" group="1" mesh="mini_abad" />
                <geom pos="0.055 0 0" quat="0.707105 0 0 0.707108" type="mesh" mesh="mini_abad" />
                <body name="thigh_hr" pos="0 -0.062 0">
                    <inertial pos="0 0.016 -0.02" quat="0.899267 -0.00195739 -0.00366412 0.437381" mass="0.634" diaginertia="0.001498 0.001498 0.001498" />
                    <joint name="abduct_hr_to_thigh_hr_j" pos="0 0 0" axis="0 -1 0" />
                    <geom quat="0.707105 0 -0.707108 0" type="mesh" contype="0" conaffinity="0" group="1" mesh="mini_upper_link" />
                    <geom quat="0.707105 0 -0.707108 0" type="mesh" mesh="mini_upper_link" />
                    <body name="shank_hr" pos="0 0 -0.209">
                        <inertial pos="0 0 -0.188673" quat="0.707107 0 0 0.707107" mass="0.214" diaginertia="0.000310727 0.000307727 3.1e-05" />
                        <joint name="thigh_hr_to_knee_hr_j" pos="0 0 0" axis="0 -1 0" />
                        <geom quat="3.26795e-07 0 1 0" type="mesh" contype="0" conaffinity="0" group="1" mesh="mini_lower_link" />
                        <geom quat="3.26795e-07 0 1 0" type="mesh" mesh="mini_lower_link" />
                        <geom size="0.015" pos="0 0 -0.18" contype="0" conaffinity="0" group="1" />
                        <geom size="0.015" pos="0 0 -0.18" />
                    </body>
                </body>
            </body>
            <body name="abduct_hl" pos="-0.19 0.049 0">
                <inertial pos="0 0.036 0" quat="0.564242 0.568689 0.421431 0.424993" mass="0.54" diaginertia="0.000577158 0.000443992 0.00036385" />
                <joint name="torso_to_abduct_hl_j" pos="0 0 0" axis="1 0 0" />
                <geom pos="0.055 0 0" quat="2.31078e-07 0.707105 -0.707108 -2.31079e-07" type="mesh" contype="0" conaffinity="0" group="1" mesh="mini_abad" />
                <geom pos="0.055 0 0" quat="2.31078e-07 0.707105 -0.707108 -2.31079e-07" type="mesh" mesh="mini_abad" />
                <body name="thigh_hl" pos="0 0.062 0">
                    <inertial pos="0 0.016 -0.02" quat="0.899267 -0.00195739 -0.00366412 0.437381" mass="0.634" diaginertia="0.001498 0.001498 0.001498" />
                    <joint name="abduct_hl_to_thigh_hl_j" pos="0 0 0" axis="0 -1 0" />
                    <geom quat="0.707105 0 -0.707108 0" type="mesh" contype="0" conaffinity="0" group="1" mesh="mini_upper_link" />
                    <geom quat="0.707105 0 -0.707108 0" type="mesh" mesh="mini_upper_link" />
                    <body name="shank_hl" pos="0 0 -0.209">
                        <inertial pos="0 0 -0.188673" quat="0.707107 0 0 0.707107" mass="0.214" diaginertia="0.000310727 0.000307727 3.1e-05" />
                        <joint name="thigh_hl_to_knee_hl_j" pos="0 0 0" axis="0 -1 0" />
                        <geom quat="3.26795e-07 0 1 0" type="mesh" contype="0" conaffinity="0" group="1" mesh="mini_lower_link" />
                        <geom quat="3.26795e-07 0 1 0" type="mesh" mesh="mini_lower_link" />
                        <geom size="0.015" pos="0 0 -0.18" contype="0" conaffinity="0" group="1" />
                        <geom size="0.015" pos="0 0 -0.18" />
                    </body>
                </body>
            </body>
        </body>
    </worldbody>

    <actuator>       
        <motor name="fl_abad_motor"   gear="1" joint="torso_to_abduct_fl_j"/>
        <motor name="fl_thigh_motor"  gear="1" joint="abduct_fl_to_thigh_fl_j"/>
        <motor name="fl_knee_motor"   gear="1" joint="thigh_fl_to_knee_fl_j"/>
        <motor name="fr_abad_motor"   gear="1" joint="torso_to_abduct_fr_j"/>
        <motor name="fr_thigh_motor"  gear="1" joint="abduct_fr_to_thigh_fr_j"/>
        <motor name="fr_knee_motor"   gear="1" joint="thigh_fr_to_knee_fr_j"/>
        <motor name="hl_abad_motor"   gear="1" joint="torso_to_abduct_hl_j"/>
        <motor name="hl_thigh_motor"  gear="1" joint="abduct_hl_to_thigh_hl_j"/>
        <motor name="hl_knee_motor"   gear="1" joint="thigh_hl_to_knee_hl_j" />
        <motor name="hr_abad_motor"   gear="1" joint="torso_to_abduct_hr_j"/>
        <motor name="hr_thigh_motor"  gear="1" joint="abduct_hr_to_thigh_hr_j"/>
        <motor name="hr_knee_motor"   gear="1" joint="thigh_hr_to_knee_hr_j"/>
    </actuator>

    <sensor>
        <jointpos name="fl_abad_pos"    joint="torso_to_abduct_fl_j"/>
        <jointpos name="fl_thigh_pos"   joint="abduct_fl_to_thigh_fl_j"/>
        <jointpos name="fl_knee_pos"    joint="thigh_fl_to_knee_fl_j"/>
        <jointpos name="fr_abad_pos"    joint="torso_to_abduct_fr_j"/>
        <jointpos name="fr_thigh_pos"   joint="abduct_fr_to_thigh_fr_j"/>
        <jointpos name="fr_knee_pos"    joint="thigh_fr_to_knee_fr_j"/>
        <jointpos name="hl_abad_pos"    joint="torso_to_abduct_hl_j"/>
        <jointpos name="hl_thigh_pos"   joint="abduct_hl_to_thigh_hl_j"/>
        <jointpos name="hl_knee_pos"    joint="thigh_hl_to_knee_hl_j" />
        <jointpos name="hr_abad_pos"    joint="torso_to_abduct_hr_j"/>
        <jointpos name="hr_thigh_pos"   joint="abduct_hr_to_thigh_hr_j"/>
        <jointpos name="hr_knee_pos"    joint="thigh_hr_to_knee_hr_j"/>

        <jointvel name="fl_abad_vel"    joint="torso_to_abduct_fl_j"/>
        <jointvel name="fl_thigh_vel"   joint="abduct_fl_to_thigh_fl_j"/>
        <jointvel name="fl_knee_vel"    joint="thigh_fl_to_knee_fl_j"/>
        <jointvel name="fr_abad_vel"    joint="torso_to_abduct_fr_j"/>
        <jointvel name="fr_thigh_vel"   joint="abduct_fr_to_thigh_fr_j"/>
        <jointvel name="fr_knee_vel"    joint="thigh_fr_to_knee_fr_j"/>
        <jointvel name="hl_abad_vel"    joint="torso_to_abduct_hl_j"/>
        <jointvel name="hl_thigh_vel"   joint="abduct_hl_to_thigh_hl_j"/>
        <jointvel name="hl_knee_vel"    joint="thigh_hl_to_knee_hl_j" />
        <jointvel name="hr_abad_vel"    joint="torso_to_abduct_hr_j"/>
        <jointvel name="hr_thigh_vel"   joint="abduct_hr_to_thigh_hr_j"/>
        <jointvel name="hr_knee_vel"    joint="thigh_hr_to_knee_hr_j"/>

        <accelerometer name="body_acc" site="imu"/>
        <gyro name="body_gyro" site="imu"/>
        <framepos name="body_pos" objtype="site" objname="imu"/>
        <framequat name="body_quat" objtype="site" objname="imu"/>
    </sensor>

    <contact>
        <exclude name="exclude_body_to_abad_fr" body1="body" body2="thigh_fr"/>
        <exclude name="exclude_body_to_abad_fl" body1="body" body2="thigh_fl"/>
        <exclude name="exclude_body_to_abad_hr" body1="body" body2="thigh_hr"/>
        <exclude name="exclude_body_to_abad_hl" body1="body" body2="thigh_hl"/>

        <exclude name="exclude_body_to_shank_fr" body1="body" body2="shank_fr"/>
        <exclude name="exclude_body_to_shank_fl" body1="body" body2="shank_fl"/>
        <exclude name="exclude_body_to_shank_hr" body1="body" body2="shank_hr"/>
        <exclude name="exclude_body_to_shank_hl" body1="body" body2="shank_hl"/>
    </contact>
</mujoco>
