<mujoco model="spirit">
  <compiler angle="radian" autolimits="true"/>
  <size njmax="500" nconmax="100"/>
  <default/>
  <worldbody>
    <light directional="true" cutoff="4" exponent="20" diffuse="1 1 1" specular="0 0 0" pos=".9 .3 2.5" dir="-.9 -.3 -2.5 "/>
    <geom size="0.1675 0.12 0.052" type="box" rgba="0.25 0.25 0.25 1"/>
    <body name="hip0" pos="0.2263 0.07 0">
      <inertial pos="0 0 0" quat="0.5 0.5 -0.5 0.5" mass="0.575" diaginertia="0.000869688 0.000669635 0.000669635"/>
      <joint name="joint_8" pos="0 0 0" axis="1 0 0"/>
      <geom size="0.055 0.04" pos="0 0.028 0" quat="0.707107 0.707107 0 0" type="cylinder" rgba="0.68 0.34 0.08 1"/>
      <body name="upper0" pos="0 0.10098 0">
        <inertial pos="0 0 0" quat="0.5 0.5 0.5 0.5" mass="0.775" diaginertia="0.001 0.001 5e-05"/>
        <joint name="joint_0" pos="0 0 0" axis="0 -1 0"/>
        <geom size="0.103 0.011 0.0275" pos="-0.103 -0.022 0" type="box" rgba="0.68 0.68 0.68 1"/>
        <body name="lower0" pos="-0.206 0 0">
          <inertial pos="0.0343333 0 0" quat="0.5 0.5 0.5 0.5" mass="0.09" diaginertia="0.00065545 0.00065545 3e-05"/>
          <joint name="joint_1" pos="0 0 0" axis="0 1 0"/>
          <geom size="0.013 0.103" pos="0.103 0 0" quat="0.707107 0 0.707107 0" type="cylinder" rgba="0.68 0.68 0.68 1"/>
          <geom size="0.02" pos="0.206 0 0" rgba="0.1 0.1 0.1 1"/>
        </body>
      </body>
    </body>
    <body name="hip1" pos="-0.2263 0.07 0">
      <inertial pos="0 0 0" quat="0.5 0.5 -0.5 0.5" mass="0.575" diaginertia="0.000869688 0.000669635 0.000669635"/>
      <joint name="joint_9" pos="0 0 0" axis="1 0 0"/>
      <geom size="0.055 0.04" pos="0 0.028 0" quat="0.707107 0.707107 0 0" type="cylinder" rgba="0.68 0.34 0.08 1"/>
      <body name="upper1" pos="0 0.10098 0">
        <inertial pos="0 0 0" quat="0.5 0.5 0.5 0.5" mass="0.775" diaginertia="0.001 0.001 5e-05"/>
        <joint name="joint_2" pos="0 0 0" axis="0 -1 0"/>
        <geom size="0.103 0.011 0.0275" pos="-0.103 -0.022 0" type="box" rgba="0.68 0.68 0.68 1"/>
        <body name="lower1" pos="-0.206 0 0">
          <inertial pos="0.0343333 0 0" quat="0.5 0.5 0.5 0.5" mass="0.09" diaginertia="0.00065545 0.00065545 3e-05"/>
          <joint name="joint_3" pos="0 0 0" axis="0 1 0"/>
          <geom size="0.013 0.103" pos="0.103 0 0" quat="0.707107 0 0.707107 0" type="cylinder" rgba="0.68 0.68 0.68 1"/>
          <geom size="0.02" pos="0.206 0 0" rgba="0.1 0.1 0.1 1"/>
        </body>
      </body>
    </body>
    <body name="hip2" pos="0.2263 -0.07 0">
      <inertial pos="0 0 0" quat="0.5 0.5 -0.5 0.5" mass="0.575" diaginertia="0.000869688 0.000669635 0.000669635"/>
      <joint name="joint_10" pos="0 0 0" axis="1 0 0"/>
      <geom size="0.055 0.04" pos="0 -0.028 0" quat="0.707107 0.707107 0 0" type="cylinder" rgba="0.68 0.34 0.08 1"/>
      <body name="upper2" pos="0 -0.10098 0">
        <inertial pos="0 0 0" quat="0.5 0.5 0.5 0.5" mass="0.775" diaginertia="0.001 0.001 5e-05"/>
        <joint name="joint_4" pos="0 0 0" axis="0 -1 0"/>
        <geom size="0.103 0.011 0.0275" pos="-0.103 0.022 0" type="box" rgba="0.68 0.68 0.68 1"/>
        <body name="lower2" pos="-0.206 0 0">
          <inertial pos="0.0343333 0 0" quat="0.5 0.5 0.5 0.5" mass="0.09" diaginertia="0.00065545 0.00065545 3e-05"/>
          <joint name="joint_5" pos="0 0 0" axis="0 1 0"/>
          <geom size="0.013 0.103" pos="0.103 0 0" quat="0.707107 0 0.707107 0" type="cylinder" rgba="0.68 0.68 0.68 1"/>
          <geom size="0.02" pos="0.206 0 0" rgba="0.1 0.1 0.1 1"/>
        </body>
      </body>
    </body>
    <body name="hip3" pos="-0.2263 -0.07 0">
      <inertial pos="0 0 0" quat="0.5 0.5 -0.5 0.5" mass="0.575" diaginertia="0.000869688 0.000669635 0.000669635"/>
      <joint name="joint_11" pos="0 0 0" axis="1 0 0"/>
      <geom size="0.055 0.04" pos="0 -0.028 0" quat="0.707107 0.707107 0 0" type="cylinder" rgba="0.68 0.34 0.08 1"/>
      <body name="upper3" pos="0 -0.10098 0">
        <inertial pos="0 0 0" quat="0.5 0.5 0.5 0.5" mass="0.775" diaginertia="0.001 0.001 5e-05"/>
        <joint name="joint_6" pos="0 0 0" axis="0 -1 0"/>
        <geom size="0.103 0.011 0.0275" pos="-0.103 0.022 0" type="box" rgba="0.68 0.68 0.68 1"/>
        <body name="lower3" pos="-0.206 0 0">
          <inertial pos="0.0343333 0 0" quat="0.5 0.5 0.5 0.5" mass="0.09" diaginertia="0.00065545 0.00065545 3e-05"/>
          <joint name="joint_7" pos="0 0 0" axis="0 1 0"/>
          <geom size="0.013 0.103" pos="0.103 0 0" quat="0.707107 0 0.707107 0" type="cylinder" rgba="0.68 0.68 0.68 1"/>
          <geom size="0.02" pos="0.206 0 0" rgba="0.1 0.1 0.1 1"/>
        </body>
      </body>
    </body>
  </worldbody>
</mujoco>
